<robot name="my_robot" xmlns:xacro="http://www.ros.org/wiki/xacro">

  <link name="robot_footprint"></link>

  <joint name="robot_footprint_joint" type="fixed">
    <origin xyz="0 0 0" rpy="0 0 0" />
    <parent link="robot_footprint"/>
    <child link="chassis" />
  </joint>

    <link name='chassis'>
        <pose>0 0 0.1 0 0 0</pose>

        <inertial>
        <mass value="15.0"/>
        <origin xyz="0.0 0 0" rpy=" 0 0 0"/>
        <inertia
            ixx="0.1" ixy="0" ixz="0"
            iyy="0.1" iyz="0"
            izz="0.1"
        />
        </inertial>

        <collision name='chassis_collision'>
        <origin xyz="0 0 0" rpy=" 0 0 0"/> 
        <geometry>
            <box size=".6 .2 .15"/>
        </geometry>
        </collision>

        <visual name='chassis_visual'>
        <origin xyz="0 0 0" rpy=" 0 0 0"/>
        <geometry>
            <box size=".6 .2 .15"/>
        </geometry>
        <material name = "Purple">
          <color rgba="0.5 0.0 0.5 1.0"/>
        </material>
        </visual>
    </link>

    <gazebo reference="chassis">
      <material>Gazebo/Blue</material>
    </gazebo>

    <link name="front_caster">
      <pose> 0 0 0.08 0 0 0 </pose>
      
      <inertial>
        <origin xyz="0.0 0.0 0.0" rpy="0.0 0.0 0.0"/>
        <mass value="0.1"/>
        <inertia ixx="0.0" ixy="0.0" ixz="0.0" iyy="0.0" iyz="0.0" izz="0.0"/>
      </inertial>
     
      <collision name='front_caster_collision'>
        <origin xyz="0 0 0" rpy=" 0 0 0"/>
        <geometry>
            <sphere radius="0.08"/>
        </geometry>
        </collision>

        <visual name='front_caster_visual'>
        <origin xyz="0 0 0" rpy=" 0 0 0"/>
        <geometry>
            <sphere radius="0.08"/>
        </geometry>
        </visual>
    </link>

    <joint name="front_caster_joint" type="continuous">
      <origin xyz="0.22 0 -0.075" rpy="0.0 0.0 0.0"/>
      <parent link="chassis"/>
      <child link="front_caster"/>
      <axis xyz="0.0 0.0 1"/>
      <limit effort="10000" velocity="1000"/>
      <dynamics damping="1.0" friction="0.01"/>
    </joint>

    <link name="rear_caster">
      <pose> 0 0 0.08 0 0 0 </pose>
      <inertial>
        <origin xyz="0.0 0.0 0.0" rpy="0.0 0.0 0.0"/>
        <mass value="0.1"/>
        <inertia ixx="0.0" ixy="0.0" ixz="0.0" iyy="0.0" iyz="0.0" izz="0.0"/>
      </inertial>
      
      <collision name='rear_caster_collision'>
        <origin xyz="0 0 0" rpy=" 0 0 0"/>
        <geometry>
            <sphere radius="0.08"/>
        </geometry>
      </collision>

      <visual name='rear_caster_visual'>
        <origin xyz="0 0 0" rpy=" 0 0 0"/>
        <geometry>
            <sphere radius="0.08"/>
        </geometry>
      </visual>
    </link>

    <joint name="rear_caster_joint" type="continuous">
      <origin xyz="-0.22 0 -0.075" rpy="0.0 0.0 0.0"/>
      <parent link="chassis"/>
      <child link="rear_caster"/>
      <axis xyz="0.0 0.0 1"/>
      <limit effort="10000" velocity="1000"/>
      <dynamics damping="1.0" friction="0.01"/>
    </joint>

    <link name = "left_wheel">
        <pose> 0 0 0.155 0 1.5707 1.5707 </pose>

        <inertial>
        <mass value="5.0"/>
        <origin xyz="0.0 0 0" rpy=" 0 1.5707 1.5707"/>
        <inertia
            ixx="0.1" ixy="0" ixz="0"
            iyy="0.1" iyz="0"
            izz="0.1"
        />
        </inertial>

        <collision name = "collision_left_wheel">
        <origin xyz="0.0 0 0" rpy=" 0 1.5707 1.5707"/>
        <geometry>
          <cylinder length="0.06" radius="0.155"/>
        </geometry>
      </collision>

      <visual name = "visual_left_wheel">
      <origin xyz="0.0 0 0" rpy=" 0 1.5707 1.5707"/>
        <geometry>
          <cylinder length="0.06" radius="0.155"/>
        </geometry>
      </visual>
    </link>

    <joint type="continuous" name="left_wheel_hinge">
        <origin xyz="0 0.135 0" rpy="0 0 0"/>
        <child link="left_wheel"/>
        <parent link="chassis"/>
        <axis xyz="0 1 0" rpy="0 0 0"/>
        <limit effort="10000" velocity="1000"/>
        <dynamics damping="1.0" friction="1.0"/>
    </joint>

    <link name = "right_wheel">
        <pose> 0 0 0.155 0 1.5707 1.5707 </pose>

        <inertial>
        <mass value="5.0"/>
        <origin xyz="0.0 0 0" rpy=" 0 1.5707 1.5707"/>
        <inertia
            ixx="0.1" ixy="0" ixz="0"
            iyy="0.1" iyz="0"
            izz="0.1"
        />
        </inertial>

        <collision name = "collision_right_wheel">
        <origin xyz="0.0 0 0" rpy=" 0 1.5707 1.5707"/>
        <geometry>
          <cylinder length="0.06" radius="0.155"/>
        </geometry>
        </collision>

      <visual name = "visual_right_wheel">
      <origin xyz="0.0 0 0" rpy=" 0 1.5707 1.5707"/>
        <geometry>
          <cylinder length="0.06" radius="0.155"/>
        </geometry>
      </visual>
    </link>

    <joint type="continuous" name="right_wheel_hinge">
        <origin xyz="0 -0.135 0" rpy="0 0 0"/>
        <child link="right_wheel"/>
        <parent link="chassis"/>
        <axis xyz="0 1 0" rpy="0 0 0"/>
        <limit effort="10000" velocity="1000"/>
        <dynamics damping="1.0" friction="1.0"/>
    </joint>

    <link name="camera">
      <inertial>
        <origin xyz="0.0 0.0 0.0" rpy="0.0 0.0 0.0"/>
        <mass value="0.1"/>
        <inertia ixx="1e-6" ixy="0.0" ixz="0.0" iyy="1e-6" iyz="0.0" izz="1e-6"/>
      </inertial>
      
      <visual name="camera_visual">
        <origin xyz="0.0 0.0 0.0" rpy="0.0 0.0 0.0"/>
        <geometry>
          <box size="0.05 0.05 0.05"/>
        </geometry>
      </visual>
      
      <collision name = "camera_collision">
        <origin xyz="0.0 0.0 0.0" rpy="0.0 0.0 0.0"/>
        <geometry>
          <box size="0.05 0.05 0.05"/>
        </geometry>
      </collision>
    </link>

    <joint name="camera_joint" type="fixed">
      <origin xyz="0.3 0.0 0.0" rpy="0.0 0.0 0.0"/>
      <parent link="chassis"/>
      <child link="camera"/>
      <axis xyz="0.0 0.0 0.0"/>
      <limit lower="0.0" upper="0.0" effort="0.0" velocity="0.0"/>
    </joint>

    <link name="hokuyo">
      <inertial>
        <origin xyz="0.0 0.0 0.0" rpy="0.0 0.0 0.0"/>
        <mass value="1e-5"/>
        <inertia ixx="1e-6" ixy="0.0" ixz="0.0" iyy="1e-6" iyz="0.0" izz="1e-6"/>
      </inertial>
      <visual name="hokuyo_visual">
        <origin xyz="0.0 0.0 0.0" rpy="0.0 0.0 0.0"/>
        <geometry>
          <mesh filename="file://$(find my_robot)/meshes/hokuyo.dae" scale="1.0 1.0 1.0"/>
        </geometry>
        <material name="">
          <color rgba="1.0 0.0 0.0 1.0"/>
          <texture filename=""/>
        </material>
      </visual>
      <collision name="hokuyo_collsion">
        <origin xyz="0.0 0.0 0.0" rpy="0.0 0.0 0.0"/>
        <geometry>
          <box size="0.1 0.1 0.1"/>
        </geometry>
      </collision>
    </link>

    <joint name="hokuyo_joint" type="fixed">
      <origin xyz="0.25 0.0 0.1" rpy="0.0 0.0 0.0"/>
      <parent link="chassis"/>
      <child link="hokuyo"/>
      <axis xyz="0.0 0.0 0.0"/>
      <limit lower="0.0" upper="0.0" effort="0.0" velocity="0.0"/>
    </joint>

    <!-- This is the plugin for the camera, LiDar, and Differential drive controller -->
    <xacro:include filename="$(find my_robot)/urdf/my_robot.gazebo"/>


</robot>